Workbook

Sheet 1) Respostas ao formulário
A1: 1 | B1: 2 | C1: 3 | D1: 4 | E1: 5 | F1: 6 | G1: 7 | H1: 8 | I1: 9 | J1: 10 | K1: 11 | L1: 12 | M1: 13 | N1: 14 | O1: 15 | P1: 16 | Q1: 17 | R1: 18 | S1: 19 | T1: 20 | U1: 21 | V1: 22 | W1: 23 | X1: 24 | Y1: 25 | Z1: 26 | AA1: 27 | AB1: 28 | AC1: 29 | AD1: 30 | AE1: 31 | AF1: 32 | AG1: 33 | AH1: 34 | AI1: 35 | AJ1: 36 | AK1: 37 | AL1: 38 | AM1: 39 | AN1: 40 | AO1: 41 | AP1: 42 | AQ1: 43 | AR1: 44 | AS1: 45 | AT1: 46 | AU1: 47 | AV1: 48 | AW1: 49 | AX1: 50 | AY1: 51 | AZ1: 52 | BA1: 53 | BB1: 54 | BC1: 55 | BD1: 56 | BE1: 57 | BF1: 58 | BG1: 59 | BH1: 60 | BI1: 61 | BJ1: 62 | BK1: 63 | BL1: 64 | BM1: 65 | BN1: 66 | BO1: 67 | BP1: 68 | BQ1: 69 | BR1: 70 | BS1: 71 | BT1: 72 | BU1: 73 | BV1: 74 | BW1: 75 | BX1: 76 | BY1: 77 | BZ1: 78 | CA1: 79 | CB1: 80 | CC1: 81 | CD1: 82 | CE1: 83 | CF1: 84 | CG1: 85 | CH1: 86 | CI1: 87 | CJ1: 88 | CK1: 89 | CL1: 90 | CM1: 91 | CN1: 92 | CO1: 93 | CP1: 94 | CQ1: 95 | CR1: 96 | CS1: 97 | CT1: 98 | CU1: 99 | CV1: 100 | CW1: 101 | CX1: 102 | CY1: 103 | CZ1: 104 | DA1: 105 | DB1: 106 | DC1: 107 | DD1: 108 | DE1: 109 | DF1: 110 | DG1: 111 | DH1: 112
A2: Column 103 | B2: Carimbo de data/hora | C2: Nome | D2: Email | E2: Telefone | F2: Usuário do Instagram | G2: Nome do cão | H2: Raça | I2: Idade | J2: Castrado? | K2: Qual o seu maior problema com seu cão hoje? | L2: Gosta de farejar o chão ou cheirar coisas? | M2: Persegue gatos, pássaros etc.? | N2: Persegue bicicletas, motos ou skates? | O2: Cava com frequência? | P2: Procura seguir odores? | Q2: Já matou e comeu algum animal? | R2: Chacoalha e "mata" brinquedos? | S2: Come muito rápido? | T2: Rouba comida ou lixo? | U2: Se esfrega em fezes ou odores fortes? | V2: Mordisca calcanhares? | W2: Encara pessoas ou cães? | X2: Transpõe obstáculos? | Y2: Se agacha observando pessoas ou cães? | Z2: Movimento de grupos chama atenção? | AA2: Brinca perseguindo cães? | AB2: Fica aflito quando alguém sai? | AC2: Se inquieta com bicicletas ou crianças? | AD2: Adora correr? | AE2: Parece atento aos seus movimentos? | AF2: Já matou algum cão ou aparenta querer matar? | AG2: Já matou e despedaçou algum cão? | AH2: Possui ímpeto de brigar? | AI2: Puxa a guia quando vê outro cão? | AJ2: Interage de forma agressiva com outros cães? | AK2: Resiste em largar objetos? | AL2: Chacoalha brinquedos de forma irritada? | AM2: Mastiga objetos com muita força? | AN2: Ataca outros cães sem sinais? | AO2: Perseguiria cães para brigar? | AP2: Late para pessoas no portão? | AQ2: Fica nervoso com movimentos externos? | AR2: Vigia portas ou janelas? | AS2: Age de forma agressiva no portão? | AT2: Precisa ser isolado para receber visitas? | AU2: Fica nervoso com convidados? | AV2: Late para convidados andando pela casa? | AW2: Late no carro para pessoas? | AX2: Fica nervoso com campainha? | AY2: Se importa com barulhos externos? | AZ2: Gosta de carregar objetos? | BA2: Gosta de brinquedos em movimento? | BB2: Traz brinquedos para brincar? | BC2: Traz brinquedos para jogar? | BD2: Fica muito empolgado para brincar? | BE2: Corre atrás de pessoas por diversão? | BF2: Corre desenfreadamente pela casa? | BG2: Procura brinquedos? | BH2: Convida outros cães para brincar? | BI2: Qualquer objeto vira brinquedo? | BJ2: Passa tranquilamente por cães? | BK2: Segue você pela casa? | BL2: Permanece amigável com cães? | BM2: Permanece amigável com pessoas? | BN2: Pede carinho? | BO2: Relaxa ao ser penteado? | BP2: Vem quando chamado? | BQ2: Brinca com pessoas desconhecidas? | BR2: Brinca com cães desconhecidos? | BS2: Permite retirar objetos da boca? | BT2: Investe contra portões com cães? | BU2: Quando inseguro, rosna ou morde? | BV2: Fica tenso com pessoas? | BW2: Fica tenso com cães? | BX2: Rosna quando manipulado? | BY2: Rosna ao ser penteado? | BZ2: Parece proteger você? | CA2: Rosna para estranhos? | CB2: Briga com cães desconhecidos? | CC2: Faz posse de brinquedos ou comida? | CD2: Tenta se afastar de portões com cães? | CE2: Quando inseguro, foge ou grita? | CF2: Evita cães? | CG2: Evita pessoas? | CH2: Tenta fugir quando manipulado? | CI2: Tenta fugir ao ser penteado? | CJ2: Persegue você como se fosse abandoná-lo? | CK2: Tenta fugir de estranhos? | CL2: Evita cães desconhecidos? | CM2: Situações novas o deixam inquieto? | CN2: Diminui o ritmo ao passar por cães? | CO2: Quando inseguro fica imóvel? | CP2: Fica imóvel diante de cães? | CQ2: Fica imóvel diante de pessoas? | CR2: Fica imóvel quando manipulado? | CS2: Fica imóvel ao ser penteado? | CT2: Fica travado quando se assusta? | CU2: Se agacha e fica imóvel diante de estranhos? | CV2: Fica tenso diante de cães desconhecidos? | CW2: Fica muito quieto como se estivesse incomodado? | CX2: Porque você acredita que a escola de cães pode te ajudar na educação do seu cão? | CZ2: CAÇA | DA2: PASTOREIO | DB2: PREDAÇÃO | DC2: TERRITORIALISMO | DD2: BRINCADEIRA | DE2: MATILHA | DF2: LUTA | DG2: FUGA | DH2: CONGELAMENTO
A3: =C3&"|"&G3 -> Tata Pereira|Eva | B3: 46225.5 | C3: Tata Pereira | D3: Adestramentotata@gmail.com | E3: 21995454595 | F3: @tata.educacao__ | G3: Eva | H3: Srd | I3: 4 anos | J3: Castrado | K3: Medo de pessoas e não gosta de passear | L3: 5 | M3: 6 | N3: 0 | O3: 4 | P3: 5 | Q3: Não | R3: 10 | S3: 3 | T3: 0 | U3: 0 | V3: 5 | W3: 0 | X3: 8 | Y3: 0 | Z3: 5 | AA3: 6 | AB3: 0 | AC3: 0 | AD3: 10 | AE3: 7 | AF3: Não | AG3: Não | AH3: 0 | AI3: 0 | AJ3: 0 | AK3: 3 | AL3: 5 | AM3: 3 | AN3: Não | AO3: 0 | AP3: 10 | AQ3: 3 | AR3: 0 | AS3: 0 | AT3: 0 | AU3: 3 | AV3: 3 | AW3: 0 | AX3: 3 | AY3: 3 | AZ3: 5 | BA3: 10 | BB3: 7 | BC3: 7 | BD3: 10 | BE3: 7 | BF3: 7 | BG3: 7 | BH3: 7 | BI3: 3 | BJ3: 10 | BK3: 5 | BL3: 10 | BM3: 5 | BN3: 10 | BO3: 8 | BP3: 10 | BQ3: 0 | BR3: 7 | BS3: 10 | BT3: 0 | BU3: 7 | BV3: 8 | BW3: 3 | BX3: 0 | BY3: 0 | BZ3: 0 | CA3: 0 | CB3: 0 | CC3: 3 | CD3: 8 | CE3: 8 | CF3: 3 | CG3: 8 | CH3: 7 | CI3: 7 | CJ3: 0 | CK3: 10 | CL3: 3 | CM3: 0 | CN3: 5 | CO3: 9 | CP3: 0 | CQ3: 8 | CR3: 10 | CS3: 10 | CT3: 4 | CU3: 7 | CV3: 3 | CW3: 5 | CX3: Quero que ela se relacione com outros cães e outras pessoas diferentes das quais ela já conhece. | CZ3: =SUM(L3:U3)+IF(P3="Sim",10,0) -> 33 | DA3: =SUM(V3:AE3) -> 41 | DB3: =SUM(AF3:AO3)+IF(AF3="Sim",10,0)+IF(AG3="Sim",10,0)+IF(AN3="Sim",10,0) -> 11 | DC3: =SUM(AP3:AY3) -> 25 | DD3: =SUM(AZ3:BI3) -> 70 | DE3: =SUM(BJ3:BS3) -> 75 | DF3: =SUM(BT3:CC3) -> 21 | DG3: =SUM(CD3:CM3) -> 54 | DH3: =SUM(CN3:CW3) -> 61
A4: =C4&"|"&G4 -> Joaquina|Paçoca | B4: 46225.568 | C4: Joaquina | D4: joahcorrea@gmail.com | E4: 21999052454 | F4: @jjjkkkk | G4: Paçoca | H4: Shihtzu | I4: 7 anos | J4: Não Castrado | K4: Late pra tudo e todos, avança, territorialista | L4: 8 | M4: 5 | N4: 9 | O4: 1 | P4: 5 | Q4: Sim | R4: 10 | S4: 9 | T4: 1 | U4: 0 | V4: 0 | W4: 7 | X4: 6 | Y4: 3 | Z4: 7 | AA4: 7 | AB4: 6 | AC4: 9 | AD4: 10 | AE4: 2 | AF4: Não | AG4: Não | AH4: 9 | AI4: 10 | AJ4: 7 | AK4: 5 | AL4: 6 | AM4: 5 | AN4: Não | AO4: 5 | AP4: 10 | AQ4: 10 | AR4: 7 | AS4: 8 | AT4: 2 | AU4: 3 | AV4: 4 | AW4: 10 | AX4: 5 | AY4: 5 | AZ4: 3 | BA4: 4 | BB4: 4 | BC4: 4 | BD4: 7 | BE4: 3 | BF4: 6 | BG4: 3 | BH4: 0 | BI4: 2 | BJ4: 5 | BK4: 10 | BL4: 1 | BM4: 4 | BN4: 0 | BO4: 5 | BP4: 9 | BQ4: 2 | BR4: 2 | BS4: 5 | BT4: 10 | BU4: 9 | BV4: 5 | BW4: 5 | BX4: 8 | BY4: 7 | BZ4: 10 | CA4: 7 | CB4: 8 | CC4: 10 | CD4: 0 | CE4: 0 | CF4: 0 | CG4: 0 | CH4: 4 | CI4: 4 | CJ4: 0 | CK4: 0 | CL4: 0 | CM4: 3 | CN4: 1 | CO4: 2 | CP4: 0 | CQ4: 0 | CR4: 2 | CS4: 1 | CT4: 0 | CU4: 0 | CV4: 2 | CW4: 0 | CX4: Porque vai ajudar as pessoas que convivem com ele a também entenderem como lidar com cachorros. | CZ4: =SUM(L4:U4)+IF(P4="Sim",10,0) -> 48 | DA4: =SUM(V4:AE4) -> 57 | DB4: =SUM(AF4:AO4)+IF(AF4="Sim",10,0)+IF(AG4="Sim",10,0)+IF(AN4="Sim",10,0) -> 47 | DC4: =SUM(AP4:AY4) -> 64 | DD4: =SUM(AZ4:BI4) -> 36 | DE4: =SUM(BJ4:BS4) -> 43 | DF4: =SUM(BT4:CC4) -> 79 | DG4: =SUM(CD4:CM4) -> 11 | DH4: =SUM(CN4:CW4) -> 8
A5: =C5&"|"&G5 -> Rachel Carla Lucas Linhares|Lili | B5: 46225.57 | C5: Rachel Carla Lucas Linhares | D5: chel.adestra@gmail.com | E5: 21 97643-5585 | F5: @chel.adestra | G5: Lili | H5: SRD | I5: 2 anos | J5: Não Castrado | K5: Insegurança | L5: 5 | M5: 0 | N5: 0 | O5: 0 | P5: 5 | Q5: Não | R5: 6 | S5: 5 | T5: 2 | U5: 0 | V5: 0 | W5: 0 | X5: 7 | Y5: 0 | Z5: 6 | AA5: 6 | AB5: 0 | AC5: 0 | AD5: 7 | AE5: 8 | AF5: Não | AG5: Não | AH5: 3 | AI5: 0 | AJ5: 4 | AK5: 3 | AL5: 0 | AM5: 0 | AN5: Não | AO5: 3 | AP5: 2 | AQ5: 3 | AR5: 3 | AS5: 1 | AT5: 5 | AU5: 5 | AV5: 5 | AW5: 0 | AX5: 5 | AY5: 6 | AZ5: 0 | BA5: 6 | BB5: 2 | BC5: 4 | BD5: 5 | BE5: 4 | BF5: 4 | BG5: 4 | BH5: 2 | BI5: 0 | BJ5: 3 | BK5: 10 | BL5: 3 | BM5: 2 | BN5: 8 | BO5: 5 | BP5: 6 | BQ5: 0 | BR5: 0 | BS5: 7 | BT5: 0 | BU5: 10 | BV5: 10 | BW5: 10 | BX5: 6 | BY5: 4 | BZ5: 10 | CA5: 7 | CB5: 7 | CC5: 7 | CD5: 8 | CE5: 5 | CF5: 10 | CG5: 10 | CH5: 5 | CI5: 5 | CJ5: 0 | CK5: 10 | CL5: 10 | CM5: 10 | CN5: 5 | CO5: 2 | CP5: 5 | CQ5: 7 | CR5: 2 | CS5: 2 | CT5: 0 | CU5: 0 | CV5: 10 | CW5: 7 | CX5: Ajudar na socialização e para melhorar a reatividade dela | CZ5: =SUM(L5:U5)+IF(P5="Sim",10,0) -> 23 | DA5: =SUM(V5:AE5) -> 34 | DB5: =SUM(AF5:AO5)+IF(AF5="Sim",10,0)+IF(AG5="Sim",10,0)+IF(AN5="Sim",10,0) -> 13 | DC5: =SUM(AP5:AY5) -> 35 | DD5: =SUM(AZ5:BI5) -> 31 | DE5: =SUM(BJ5:BS5) -> 44 | DF5: =SUM(BT5:CC5) -> 71 | DG5: =SUM(CD5:CM5) -> 73 | DH5: =SUM(CN5:CW5) -> 40
A6: =C6&"|"&G6 -> Luiza Faria |Julieta | B6: 46257.429 | C6: Luiza Faria | D6: luizzafpereira@gmail.com | E6: 31985894327 | F6: @luizapfaria | G6: Julieta | H6: Dachshund | I6: 1 ano e 2 meses | J6: Não Castrado | K6: Agitação e medo | L6: 10 | M6: 10 | N6: 2 | O6: 5 | P6: 10 | Q6: Não | R6: 10 | S6: 4 | T6: 10 | U6: 0 | V6: 0 | W6: 6 | X6: 10 | Y6: 10 | Z6: 10 | AA6: 8 | AB6: 5 | AC6: 5 | AD6: 10 | AE6: 10 | AF6: Não | AG6: Não | AH6: 0 | AI6: 6 | AJ6: 0 | AK6: 10 | AL6: 0 | AM6: 6 | AN6: Não | AO6: 0 | AP6: 10 | AQ6: 5 | AR6: 8 | AS6: 0 | AT6: 0 | AU6: 4 | AV6: 0 | AW6: 6 | AX6: 0 | AY6: 10 | AZ6: 10 | BA6: 10 | BB6: 10 | BC6: 10 | BD6: 10 | BE6: 10 | BF6: 10 | BG6: 10 | BH6: 6 | BI6: 10 | BJ6: 4 | BK6: 10 | BL6: 5 | BM6: 10 | BN6: 10 | BO6: 10 | BP6: 10 | BQ6: 0 | BR6: 0 | BS6: 5 | BT6: 0 | BU6: 6 | BV6: 3 | BW6: 8 | BX6: 6 | BY6: 0 | BZ6: 10 | CA6: 3 | CB6: 0 | CC6: 10 | CD6: 10 | CE6: 10 | CF6: 10 | CG6: 10 | CH6: 10 | CI6: 0 | CJ6: 10 | CK6: 10 | CL6: 10 | CM6: 4 | CN6: 6 | CO6: 5 | CP6: 8 | CQ6: 8 | CR6: 8 | CS6: 0 | CT6: 0 | CU6: 6 | CV6: 10 | CW6: 0 | CX6: Acredito que na escola a Julieta consegue gastar sua energia de forma saudável, além de desenvolver uma melhor socialização com outros cães e com pessoas. Também acredito que esse ambiente pode ajudá-la a se sentir mais segura e confiante. | CZ6: =SUM(L6:U6)+IF(P6="Sim",10,0) -> 61 | DA6: =SUM(V6:AE6) -> 74 | DB6: =SUM(AF6:AO6)+IF(AF6="Sim",10,0)+IF(AG6="Sim",10,0)+IF(AN6="Sim",10,0) -> 22 | DC6: =SUM(AP6:AY6) -> 43 | DD6: =SUM(AZ6:BI6) -> 96 | DE6: =SUM(BJ6:BS6) -> 64 | DF6: =SUM(BT6:CC6) -> 46 | DG6: =SUM(CD6:CM6) -> 84 | DH6: =SUM(CN6:CW6) -> 51
A7: =C7&"|"&G7 -> Joyce Silva de Oliveira |Zé Pequeno | B7: 46257.431 | C7: Joyce Silva de Oliveira | D7: Joyceolvra52@gmail.com | E7: 2196991-1298 | F7: @_joyceolvra | G7: Zé Pequeno | H7: Chihuahua | I7: 1 ano e 6 meses | J7: Não Castrado | K7: Aproximadamente com outros cachorros em passeios na rua. | L7: 10 | M7: 10 | N7: 10 | O7: 7 | P7: 7 | Q7: Não | R7: 7 | S7: 0 | T7: 4 | U7: 0 | V7: 0 | W7: 10 | X7: 4 | Y7: 2 | Z7: 6 | AA7: 4 | AB7: 0 | AC7: 10 | AD7: 10 | AE7: 10 | AF7: Não | AG7: Não | AH7: 9 | AI7: 10 | AJ7: 10 | AK7: 8 | AL7: 9 | AM7: 7 | AN7: Não | AO7: 9 | AP7: 10 | AQ7: 5 | AR7: 10 | AS7: 6 | AT7: 2 | AU7: 5 | AV7: 2 | AW7: 2 | AX7: 2 | AY7: 5 | AZ7: 3 | BA7: 8 | BB7: 9 | BC7: 10 | BD7: 10 | BE7: 3 | BF7: 7 | BG7: 8 | BH7: 2 | BI7: 8 | BJ7: 0 | BK7: 7 | BL7: 5 | BM7: 7 | BN7: 10 | BO7: 8 | BP7: 9 | BQ7: 7 | BR7: 0 | BS7: 5 | BT7: 8 | BU7: 8 | BV7: 7 | BW7: 10 | BX7: 7 | BY7: 0 | BZ7: 0 | CA7: 5 | CB7: 10 | CC7: 7 | CD7: 0 | CE7: 0 | CF7: 0 | CG7: 0 | CH7: 1 | CI7: 0 | CJ7: 0 | CK7: 0 | CL7: 0 | CM7: 0 | CN7: 0 | CO7: 0 | CP7: 0 | CQ7: 0 | CR7: 2 | CS7: 3 | CT7: 0 | CU7: 0 | CV7: 10 | CW7: 0 | CX7: Melhora no bem-estar e convivência com outros cães. | CZ7: =SUM(L7:U7)+IF(P7="Sim",10,0) -> 55 | DA7: =SUM(V7:AE7) -> 56 | DB7: =SUM(AF7:AO7)+IF(AF7="Sim",10,0)+IF(AG7="Sim",10,0)+IF(AN7="Sim",10,0) -> 62 | DC7: =SUM(AP7:AY7) -> 49 | DD7: =SUM(AZ7:BI7) -> 68 | DE7: =SUM(BJ7:BS7) -> 58 | DF7: =SUM(BT7:CC7) -> 62 | DG7: =SUM(CD7:CM7) -> 1 | DH7: =SUM(CN7:CW7) -> 15
A8: =C8&"|"&G8 -> Joyce Silva de Oliveira |Bené | B8: 46257.441 | C8: Joyce Silva de Oliveira | D8: Joyceolvra52@gmail.com | E8: 21 96991-1298 | F8: @_joyceolvra | G8: Bené | H8: Chihuahua | I8: 11 meses | J8: Não Castrado | K8: Entrada de pessoas em casa. | L8: 10 | M8: 8 | N8: 3 | O8: 2 | P8: 2 | Q8: Não | R8: 8 | S8: 9 | T8: 10 | U8: 0 | V8: 8 | W8: 7 | X8: 10 | Y8: 10 | Z8: 7 | AA8: 9 | AB8: 0 | AC8: 4 | AD8: 7 | AE8: 8 | AF8: Não | AG8: Não | AH8: 6 | AI8: 5 | AJ8: 5 | AK8: 0 | AL8: 0 | AM8: 6 | AN8: Não | AO8: 0 | AP8: 8 | AQ8: 7 | AR8: 8 | AS8: 0 | AT8: 2 | AU8: 6 | AV8: 5 | AW8: 0 | AX8: 5 | AY8: 6 | AZ8: 10 | BA8: 9 | BB8: 2 | BC8: 0 | BD8: 10 | BE8: 4 | BF8: 7 | BG8: 8 | BH8: 8 | BI8: 10 | BJ8: 7 | BK8: 8 | BL8: 8 | BM8: 8 | BN8: 7 | BO8: 10 | BP8: 8 | BQ8: 8 | BR8: 6 | BS8: 10 | BT8: 5 | BU8: 0 | BV8: 7 | BW8: 6 | BX8: 0 | BY8: 0 | BZ8: 8 | CA8: 0 | CB8: 5 | CC8: 10 | CD8: 6 | CE8: 7 | CF8: 5 | CG8: 4 | CH8: 2 | CI8: 0 | CJ8: 0 | CK8: 2 | CL8: 6 | CM8: 8 | CN8: 6 | CO8: 7 | CP8: 3 | CQ8: 2 | CR8: 8 | CS8: 10 | CT8: 5 | CU8: 2 | CV8: 7 | CW8: 0 | CX8: Atividades mentais e físicas, e mantê-lo equilibrado. | CZ8: =SUM(L8:U8)+IF(P8="Sim",10,0) -> 52 | DA8: =SUM(V8:AE8) -> 70 | DB8: =SUM(AF8:AO8)+IF(AF8="Sim",10,0)+IF(AG8="Sim",10,0)+IF(AN8="Sim",10,0) -> 22 | DC8: =SUM(AP8:AY8) -> 47 | DD8: =SUM(AZ8:BI8) -> 68 | DE8: =SUM(BJ8:BS8) -> 80 | DF8: =SUM(BT8:CC8) -> 41 | DG8: =SUM(CD8:CM8) -> 40 | DH8: =SUM(CN8:CW8) -> 50
A9: =C9&"|"&G9 -> Tereza Cristina Cruz|Luna | B9: 46257.49 | C9: Tereza Cristina Cruz | D9: cristiccruz@gmail.com | E9: 21999174705 | F9: tcbcc24 | G9: Luna | H9: SRD | I9: 3 a 7 m | J9: Castrado | K9: A sua doença, diabetes | L9: 10 | M9: 5 | N9: 0 | O9: 7 | P9: 10 | Q9: Não | R9: 7 | S9: 10 | T9: 6 | U9: 0 | V9: 0 | W9: 3 | X9: 9 | Y9: 10 | Z9: 10 | AA9: 4 | AB9: 0 | AC9: 3 | AD9: 10 | AE9: 10 | AF9: Não | AG9: Não | AH9: 0 | AI9: 2 | AJ9: 2 | AK9: 2 | AL9: 2 | AM9: 9 | AN9: Não | AO9: 0 | AP9: 9 | AQ9: 9 | AR9: 9 | AS9: 7 | AT9: 10 | AU9: 10 | AV9: 10 | AW9: 0 | AX9: 10 | AY9: 3 | AZ9: 0 | BA9: 0 | BB9: 0 | BC9: 0 | BD9: 9 | BE9: 10 | BF9: 7 | BG9: 0 | BH9: 5 | BI9: 0 | BJ9: 4 | BK9: 10 | BL9: 10 | BM9: 2 | BN9: 10 | BO9: 0 | BP9: 10 | BQ9: 0 | BR9: 0 | BS9: 10 | BT9: 0 | BU9: 0 | BV9: 10 | BW9: 0 | BX9: 0 | BY9: 0 | BZ9: 10 | CA9: 0 | CB9: 4 | CC9: 0 | CD9: 0 | CE9: 0 | CF9: 0 | CG9: 0 | CH9: 5 | CI9: 5 | CJ9: 10 | CK9: 0 | CL9: 0 | CM9: 10 | CN9: 0 | CO9: 0 | CP9: 0 | CQ9: 2 | CR9: 0 | CS9: 0 | CT9: 3 | CU9: 0 | CV9: 3 | CW9: 0 | CX9: Pela experiência da equipe no manejo com as dificuldades dos cães e na leitura comportamental. | CZ9: =SUM(L9:U9)+IF(P9="Sim",10,0) -> 55 | DA9: =SUM(V9:AE9) -> 59 | DB9: =SUM(AF9:AO9)+IF(AF9="Sim",10,0)+IF(AG9="Sim",10,0)+IF(AN9="Sim",10,0) -> 17 | DC9: =SUM(AP9:AY9) -> 77 | DD9: =SUM(AZ9:BI9) -> 31 | DE9: =SUM(BJ9:BS9) -> 56 | DF9: =SUM(BT9:CC9) -> 24 | DG9: =SUM(CD9:CM9) -> 30 | DH9: =SUM(CN9:CW9) -> 8
A10: =C10&"|"&G10 -> Tereza Cristina Cruz|Jade | B10: 46257.496 | C10: Tereza Cristina Cruz | D10: cristiccruz@gmail.com | E10: 21999174705 | F10: tcbcc24 | G10: Jade | H10: SRD | I10: 3a7m | J10: Não Castrado | K10: Socialização com outros animais ( de casa e na rua) e visitas | L10: 10 | M10: 7 | N10: 0 | O10: 0 | P10: 10 | Q10: Não | R10: 0 | S10: 0 | T10: 0 | U10: 0 | V10: 0 | W10: 10 | X10: 0 | Y10: 6 | Z10: 9 | AA10: 6 | AB10: 0 | AC10: 0 | AD10: 10 | AE10: 10 | AF10: Não | AG10: Não | AH10: 6 | AI10: 7 | AJ10: 7 | AK10: 7 | AL10: 0 | AM10: 0 | AN10: Não | AO10: 2 | AP10: 10 | AQ10: 9 | AR10: 10 | AS10: 9 | AT10: 10 | AU10: 10 | AV10: 10 | AW10: 7 | AX10: 10 | AY10: 10 | AZ10: 10 | BA10: 0 | BB10: 0 | BC10: 0 | BD10: 10 | BE10: 10 | BF10: 10 | BG10: 0 | BH10: 0 | BI10: 0 | BJ10: 6 | BK10: 10 | BL10: 0 | BM10: 0 | BN10: 10 | BO10: 10 | BP10: 10 | BQ10: 0 | BR10: 0 | BS10: 10 | BT10: 10 | BU10: 0 | BV10: 10 | BW10: 10 | BX10: 0 | BY10: 0 | BZ10: 10 | CA10: 0 | CB10: 0 | CC10: 10 | CD10: 0 | CE10: 10 | CF10: 0 | CG10: 0 | CH10: 0 | CI10: 0 | CJ10: 10 | CK10: 10 | CL10: 10 | CM10: 10 | CN10: 6 | CO10: 0 | CP10: 0 | CQ10: 0 | CR10: 5 | CS10: 5 | CT10: 0 | CU10: 0 | CV10: 10 | CW10: 0 | CX10: Socialização Com Outros cães e interagir com Pessoas fora de casa. | CZ10: =SUM(L10:U10)+IF(P10="Sim",10,0) -> 27 | DA10: =SUM(V10:AE10) -> 51 | DB10: =SUM(AF10:AO10)+IF(AF10="Sim",10,0)+IF(AG10="Sim",10,0)+IF(AN10="Sim",10,0) -> 29 | DC10: =SUM(AP10:AY10) -> 95 | DD10: =SUM(AZ10:BI10) -> 40 | DE10: =SUM(BJ10:BS10) -> 56 | DF10: =SUM(BT10:CC10) -> 50 | DG10: =SUM(CD10:CM10) -> 50 | DH10: =SUM(CN10:CW10) -> 26
A11: =C11&"|"&G11 -> Milla souza |Dumbo | B11: 46257.583 | C11: Milla souza | D11: Millalima051@gmail.com | E11: 21992763069 | F11: @ohmillasouza | G11: Dumbo | H11: Sdr | I11: 1 ano | J11: Não Castrado | K11: A euforia ao ver outro cachorro na rua | L11: 10 | M11: 10 | N11: 0 | O11: 3 | P11: 8 | Q11: Sim | R11: 6 | S11: 4 | T11: 6 | U11: 0 | V11: 0 | W11: 7 | X11: 8 | Y11: 10 | Z11: 6 | AA11: 10 | AB11: 8 | AC11: 4 | AD11: 10 | AE11: 10 | AF11: Não | AG11: Não | AH11: 5 | AI11: 10 | AJ11: 4 | AK11: 10 | AL11: 0 | AM11: 10 | AN11: Não | AO11: 0 | AP11: 9 | AQ11: 0 | AR11: 10 | AS11: 0 | AT11: 8 | AU11: 0 | AV11: 0 | AW11: 0 | AX11: 0 | AY11: 0 | AZ11: 9 | BA11: 10 | BB11: 10 | BC11: 10 | BD11: 10 | BE11: 10 | BF11: 10 | BG11: 10 | BH11: 10 | BI11: 10 | BJ11: 8 | BK11: 9 | BL11: 10 | BM11: 10 | BN11: 10 | BO11: 7 | BP11: 8 | BQ11: 10 | BR11: 10 | BS11: 8 | BT11: 8 | BU11: 5 | BV11: 0 | BW11: 4 | BX11: 0 | BY11: 0 | BZ11: 9 | CA11: 0 | CB11: 4 | CC11: 8 | CD11: 4 | CE11: 1 | CF11: 0 | CG11: 0 | CH11: 5 | CI11: 5 | CJ11: 6 | CK11: 0 | CL11: 0 | CM11: 5 | CN11: 8 | CO11: 1 | CP11: 4 | CQ11: 0 | CR11: 6 | CS11: 5 | CT11: 0 | CU11: 0 | CV11: 0 | CW11: 0 | CX11: A escola me ajuda a reeducar meus comportamentos para lidar com o dia a dia do meu pet, dessa forma, consigo ter um cão mais equilibrado dentro de casa | CZ11: =SUM(L11:U11)+IF(P11="Sim",10,0) -> 47 | DA11: =SUM(V11:AE11) -> 73 | DB11: =SUM(AF11:AO11)+IF(AF11="Sim",10,0)+IF(AG11="Sim",10,0)+IF(AN11="Sim",10,0) -> 39 | DC11: =SUM(AP11:AY11) -> 27 | DD11: =SUM(AZ11:BI11) -> 99 | DE11: =SUM(BJ11:BS11) -> 90 | DF11: =SUM(BT11:CC11) -> 38 | DG11: =SUM(CD11:CM11) -> 26 | DH11: =SUM(CN11:CW11) -> 24
A12: =C12&"|"&G12 -> Lusinete dos Santos Cobe |Zaion | B12: 46257.766 | C12: Lusinete dos Santos Cobe | D12: lusinetebarbosa1971@gmail.com | E12: (21)997204800 | F12: Não | G12: Zaion | H12: Buldogue com vira lata | I12: 7 Meses | J12: Não Castrado | K12: Desobediência | L12: 10 | M12: 10 | N12: 10 | O12: 10 | P12: 10 | Q12: Não | R12: 10 | S12: 10 | T12: 0 | U12: 0 | V12: 0 | W12: 0 | X12: 10 | Y12: 0 | Z12: 10 | AA12: 10 | AB12: 0 | AC12: 10 | AD12: 10 | AE12: 10 | AF12: Não | AG12: Não | AH12: 0 | AI12: 10 | AJ12: 0 | AK12: 0 | AL12: 0 | AM12: 10 | AN12: Não | AO12: 0 | AP12: 10 | AQ12: 10 | AR12: 10 | AS12: 0 | AT12: 0 | AU12: 0 | AV12: 0 | AW12: 0 | AX12: 10 | AY12: 10 | AZ12: 10 | BA12: 10 | BB12: 10 | BC12: 10 | BD12: 10 | BE12: 10 | BF12: 10 | BG12: 10 | BH12: 10 | BI12: 10 | BJ12: 10 | BK12: 10 | BL12: 10 | BM12: 10 | BN12: 10 | BO12: 10 | BP12: 10 | BQ12: 10 | BR12: 10 | BS12: 10 | BT12: 0 | BU12: 0 | BV12: 10 | BW12: 0 | BX12: 0 | BY12: 0 | BZ12: 10 | CA12: 0 | CB12: 0 | CC12: 0 | CD12: 10 | CE12: 10 | CF12: 10 | CG12: 0 | CH12: 10 | CI12: 0 | CJ12: 0 | CK12: 0 | CL12: 10 | CM12: 0 | CN12: 10 | CO12: 0 | CP12: 0 | CQ12: 0 | CR12: 10 | CS12: 0 | CT12: 0 | CU12: 0 | CV12: 0 | CW12: 10 | CX12: Porque eu acho que ele pode melhorar o seu comportamento | CZ12: =SUM(L12:U12)+IF(P12="Sim",10,0) -> 70 | DA12: =SUM(V12:AE12) -> 60 | DB12: =SUM(AF12:AO12)+IF(AF12="Sim",10,0)+IF(AG12="Sim",10,0)+IF(AN12="Sim",10,0) -> 20 | DC12: =SUM(AP12:AY12) -> 50 | DD12: =SUM(AZ12:BI12) -> 100 | DE12: =SUM(BJ12:BS12) -> 100 | DF12: =SUM(BT12:CC12) -> 20 | DG12: =SUM(CD12:CM12) -> 50 | DH12: =SUM(CN12:CW12) -> 30
A13: =C13&"|"&G13 -> Sergio Vinícius Alves Barros |Martín Silva | B13: 46257.899 | C13: Sergio Vinícius Alves Barros | D13: sergiovinicius.ab@gmail.com | E13: 21982738364 | F13: Sergioviniciusab | G13: Martín Silva | H13: Fox terrier Paulistinha | I13: 7 | J13: Castrado | K13: Come cocô | L13: 10 | M13: 9 | N13: 0 | O13: 10 | P13: 7 | Q13: Não | R13: 9 | S13: 8 | T13: 0 | U13: 0 | V13: 0 | W13: 5 | X13: 3 | Y13: 0 | Z13: 3 | AA13: 0 | AB13: 6 | AC13: 0 | AD13: 10 | AE13: 10 | AF13: Não | AG13: Não | AH13: 5 | AI13: 9 | AJ13: 9 | AK13: 3 | AL13: 8 | AM13: 8 | AN13: Não | AO13: 7 | AP13: 8 | AQ13: 7 | AR13: 7 | AS13: 8 | AT13: 0 | AU13: 0 | AV13: 0 | AW13: 0 | AX13: 0 | AY13: 7 | AZ13: 7 | BA13: 8 | BB13: 9 | BC13: 7 | BD13: 9 | BE13: 8 | BF13: 4 | BG13: 9 | BH13: 0 | BI13: 3 | BJ13: 0 | BK13: 9 | BL13: 5 | BM13: 10 | BN13: 3 | BO13: 7 | BP13: 7 | BQ13: 7 | BR13: 0 | BS13: 10 | BT13: 8 | BU13: 3 | BV13: 2 | BW13: 10 | BX13: 7 | BY13: 0 | BZ13: 4 | CA13: 0 | CB13: 8 | CC13: 0 | CD13: 0 | CE13: 5 | CF13: 5 | CG13: 0 | CH13: 2 | CI13: 2 | CJ13: 3 | CK13: 2 | CL13: 7 | CM13: 8 | CN13: 9 | CO13: 1 | CP13: 5 | CQ13: 0 | CR13: 0 | CS13: 5 | CT13: 5 | CU13: 2 | CV13: 10 | CW13: 8 | CX13: Passeio, hobby faro, comer mais devagar, evitar comer coco. | CZ13: =SUM(L13:U13)+IF(P13="Sim",10,0) -> 53 | DA13: =SUM(V13:AE13) -> 37 | DB13: =SUM(AF13:AO13)+IF(AF13="Sim",10,0)+IF(AG13="Sim",10,0)+IF(AN13="Sim",10,0) -> 49 | DC13: =SUM(AP13:AY13) -> 37 | DD13: =SUM(AZ13:BI13) -> 64 | DE13: =SUM(BJ13:BS13) -> 58 | DF13: =SUM(BT13:CC13) -> 42 | DG13: =SUM(CD13:CM13) -> 34 | DH13: =SUM(CN13:CW13) -> 45
A14: =C14&"|"&G14 -> Heloisa Pisa|Olívia | B14: 46257.921 | C14: Heloisa Pisa | D14: Hspisa@gmail.com | E14: 2188792290 | F14: @hspisa | G14: Olívia | H14: Pastor australiano | I14: 1 ano | J14: Não Castrado | K14: Dificuldade para passear, regular euforia com pessoas novas na casa | L14: 9 | M14: 6 | N14: 0 | O14: 2 | P14: 8 | Q14: Não | R14: 9 | S14: 7 | T14: 3 | U14: 0 | V14: 1 | W14: 7 | X14: 9 | Y14: 4 | Z14: 8 | AA14: 8 | AB14: 1 | AC14: 5 | AD14: 10 | AE14: 10 | AF14: Não | AG14: Não | AH14: 0 | AI14: 10 | AJ14: 0 | AK14: 8 | AL14: 2 | AM14: 5 | AN14: Não | AO14: 0 | AP14: 0 | AQ14: 6 | AR14: 8 | AS14: 0 | AT14: 2 | AU14: 2 | AV14: 0 | AW14: 3 | AX14: 9 | AY14: 3 | AZ14: 8 | BA14: 10 | BB14: 10 | BC14: 9 | BD14: 8 | BE14: 4 | BF14: 7 | BG14: 7 | BH14: 7 | BI14: 7 | BJ14: 0 | BK14: 10 | BL14: 9 | BM14: 10 | BN14: 8 | BO14: 8 | BP14: 7 | BQ14: 9 | BR14: 10 | BS14: 7 | BT14: 1 | BU14: 1 | BV14: 1 | BW14: 1 | BX14: 0 | BY14: 0 | BZ14: 5 | CA14: 0 | CB14: 0 | CC14: 1 | CD14: 0 | CE14: 2 | CF14: 0 | CG14: 0 | CH14: 5 | CI14: 3 | CJ14: 1 | CK14: 0 | CL14: 0 | CM14: 8 | CN14: 0 | CO14: 6 | CP14: 1 | CQ14: 2 | CR14: 0 | CS14: 0 | CT14: 5 | CU14: 0 | CV14: 0 | CW14: 1 | CX14: Para ajudar o cão a ter mais autocontrole, dosando as emoções tanto na rua quanto em situações de euforia (ex, visitas em casa). Ajuda o cão a ter um espaço de interação com outros cães. | CZ14: =SUM(L14:U14)+IF(P14="Sim",10,0) -> 44 | DA14: =SUM(V14:AE14) -> 63 | DB14: =SUM(AF14:AO14)+IF(AF14="Sim",10,0)+IF(AG14="Sim",10,0)+IF(AN14="Sim",10,0) -> 25 | DC14: =SUM(AP14:AY14) -> 33 | DD14: =SUM(AZ14:BI14) -> 77 | DE14: =SUM(BJ14:BS14) -> 78 | DF14: =SUM(BT14:CC14) -> 10 | DG14: =SUM(CD14:CM14) -> 19 | DH14: =SUM(CN14:CW14) -> 15
A15: =C15&"|"&G15 -> Barbara Menezes |Poliana | B15: 46258.38 | C15: Barbara Menezes | D15: barbara.menezes04@gmail.com | E15: 21979668998 | F15: Barbara Menezes | G15: Poliana | H15: SRD | I15: 5 | J15: Castrado | K15: Não responder a comandos quando está com medo. Ao ter medo ou chora ou ataca | L15: 10 | M15: 10 | N15: 0 | O15: 4 | P15: 4 | Q15: Não | R15: 9 | S15: 3 | T15: 2 | U15: 0 | V15: 0 | W15: 0 | X15: 5 | Y15: 2 | Z15: 10 | AA15: 8 | AB15: 10 | AC15: 10 | AD15: 10 | AE15: 10 | AF15: Não | AG15: Não | AH15: 1 | AI15: 7 | AJ15: 0 | AK15: 10 | AL15: 10 | AM15: 3 | AN15: Não | AO15: 0 | AP15: 10 | AQ15: 10 | AR15: 8 | AS15: 4 | AT15: 0 | AU15: 0 | AV15: 0 | AW15: 0 | AX15: 10 | AY15: 10 | AZ15: 7 | BA15: 5 | BB15: 10 | BC15: 10 | BD15: 10 | BE15: 10 | BF15: 10 | BG15: 10 | BH15: 10 | BI15: 10 | BJ15: 5 | BK15: 7 | BL15: 10 | BM15: 10 | BN15: 10 | BO15: 10 | BP15: 8 | BQ15: 10 | BR15: 10 | BS15: 5 | BT15: 5 | BU15: 8 | BV15: 0 | BW15: 0 | BX15: 3 | BY15: 0 | BZ15: 3 | CA15: 0 | CB15: 0 | CC15: 5 | CD15: 0 | CE15: 8 | CF15: 0 | CG15: 0 | CH15: 0 | CI15: 0 | CJ15: 0 | CK15: 0 | CL15: 0 | CM15: 8 | CN15: 8 | CO15: 4 | CP15: 0 | CQ15: 0 | CR15: 0 | CS15: 0 | CT15: 0 | CU15: 0 | CV15: 0 | CW15: 0 | CX15: Por conhecer a necessidade dele. | CZ15: =SUM(L15:U15)+IF(P15="Sim",10,0) -> 42 | DA15: =SUM(V15:AE15) -> 65 | DB15: =SUM(AF15:AO15)+IF(AF15="Sim",10,0)+IF(AG15="Sim",10,0)+IF(AN15="Sim",10,0) -> 31 | DC15: =SUM(AP15:AY15) -> 52 | DD15: =SUM(AZ15:BI15) -> 92 | DE15: =SUM(BJ15:BS15) -> 85 | DF15: =SUM(BT15:CC15) -> 24 | DG15: =SUM(CD15:CM15) -> 16 | DH15: =SUM(CN15:CW15) -> 12
A16: =C16&"|"&G16 -> Joelma Ferreira |Duque | B16: 46255.933 | C16: Joelma Ferreira | D16: joelmafsfernandes@yahoo.com.br | E16: 21993546535 | F16: Não | G16: Duque | H16: Vira lata | I16: 9 anos | J16: Não Castrado | K16: Destrói a casa quando fica sozinho. | L16: 8 | M16: 8 | N16: 3 | O16: 5 | P16: 7 | Q16: Não | R16: 7 | S16: 7 | T16: 4 | U16: 0 | V16: 0 | W16: 7 | X16: 9 | Y16: 3 | Z16: 6 | AA16: 8 | AB16: 10 | AC16: 5 | AD16: 8 | AE16: 10 | AF16: Não | AG16: Não | AH16: 7 | AI16: 8 | AJ16: 6 | AK16: 6 | AL16: 6 | AM16: 5 | AN16: Não | AO16: 6 | AP16: 7 | AQ16: 6 | AR16: 9 | AS16: 8 | AT16: 6 | AU16: 5 | AV16: 4 | AW16: 0 | AX16: 4 | AY16: 7 | AZ16: 2 | BA16: 8 | BB16: 8 | BC16: 8 | BD16: 8 | BE16: 5 | BF16: 2 | BG16: 4 | BH16: 3 | BI16: 3 | BJ16: 5 | BK16: 5 | BL16: 5 | BM16: 7 | BN16: 8 | BO16: 10 | BP16: 8 | BQ16: 3 | BR16: 4 | BS16: 7 | BT16: 7 | BU16: 4 | BV16: 5 | BW16: 7 | BX16: 4 | BY16: 0 | BZ16: 8 | CA16: 4 | CB16: 6 | CC16: 2 | CD16: 1 | CE16: 4 | CF16: 5 | CG16: 4 | CH16: 3 | CI16: 0 | CJ16: 8 | CK16: 4 | CL16: 6 | CM16: 5 | CN16: 3 | CO16: 5 | CP16: 4 | CQ16: 3 | CR16: 3 | CS16: 0 | CT16: 6 | CU16: 2 | CV16: 6 | CW16: 5 | CX16: Para reduzir a ansiedade e hiperapego. | CZ16: =SUM(L16:U16)+IF(P16="Sim",10,0) -> 49 | DA16: =SUM(V16:AE16) -> 66 | DB16: =SUM(AF16:AO16)+IF(AF16="Sim",10,0)+IF(AG16="Sim",10,0)+IF(AN16="Sim",10,0) -> 44 | DC16: =SUM(AP16:AY16) -> 56 | DD16: =SUM(AZ16:BI16) -> 51 | DE16: =SUM(BJ16:BS16) -> 62 | DF16: =SUM(BT16:CC16) -> 47 | DG16: =SUM(CD16:CM16) -> 40 | DH16: =SUM(CN16:CW16) -> 37

Sheet 2) Análise Anaminese
B2: Pesquisar: | C2: Joelma Ferreira |Duque | F2: Aviso: nesta etapa da análise, basta pesquisar o nome do cão que você deseja analisar.
B5: ANÁLISE COMPORTAMENTAL DO CÃO | E5: =VLOOKUP($C$2,'1) Respostas ao formulário'!$A:$DH,'1) Respostas ao formulário'!$G$1,FALSE) -> Duque | F5: =VLOOKUP($C$2,'1) Respostas ao formulário'!$A:$DH,'1) Respostas ao formulário'!$H$1,FALSE) -> Vira lata | G5: =VLOOKUP($C$2,'1) Respostas ao formulário'!$A:$DH,'1) Respostas ao formulário'!$I$1,FALSE) -> 9 anos | H5: =VLOOKUP($C$2,'1) Respostas ao formulário'!$A:$DH,'1) Respostas ao formulário'!$J$1,FALSE) -> Não Castrado | I5: Responsável | J5: =VLOOKUP($C$2,'1) Respostas ao formulário'!$A:$DH,'1) Respostas ao formulário'!$C$1,FALSE) -> Joelma Ferreira
B7: DRIVES | C7: CAÇA | D7: PASTOREIO | E7: PREDAÇÃO | F7: TERRITORIALISMO | G7: BRINCADEIRA | H7: MATILHA | I7: LUTA | J7: FUGA | K7: CONGELAMENTO
B8: PONTUAÇÃO | C8: =VLOOKUP($C$2,'1) Respostas ao formulário'!$A:$DH,'1) Respostas ao formulário'!CZ1,FALSE) -> 49 | D8: =VLOOKUP($C$2,'1) Respostas ao formulário'!$A:$DH,'1) Respostas ao formulário'!DA1,FALSE) -> 66 | E8: =VLOOKUP($C$2,'1) Respostas ao formulário'!$A:$DH,'1) Respostas ao formulário'!DB1,FALSE) -> 44 | F8: =VLOOKUP($C$2,'1) Respostas ao formulário'!$A:$DH,'1) Respostas ao formulário'!DC1,FALSE) -> 56 | G8: =VLOOKUP($C$2,'1) Respostas ao formulário'!$A:$DH,'1) Respostas ao formulário'!DD1,FALSE) -> 51 | H8: =VLOOKUP($C$2,'1) Respostas ao formulário'!$A:$DH,'1) Respostas ao formulário'!DE1,FALSE) -> 62 | I8: =VLOOKUP($C$2,'1) Respostas ao formulário'!$A:$DH,'1) Respostas ao formulário'!DF1,FALSE) -> 47 | J8: =VLOOKUP($C$2,'1) Respostas ao formulário'!$A:$DH,'1) Respostas ao formulário'!DG1,FALSE) -> 40 | K8: =VLOOKUP($C$2,'1) Respostas ao formulário'!$A:$DH,'1) Respostas ao formulário'!DH1,FALSE) -> 37
B9: CLASSIFICAÇÃO | C9: =IF(C8="","",IF(OR(C8<0,C8>100),"Pontuação inválida",IF(C8<=20,"Muito baixo",IF(C8<=40,"Baixo",IF(C8<=60,"Moderado",IF(C8<=80,"Alto","Muito alto")))))) -> Moderado | D9: =IF(D8="","",IF(OR(D8<0,D8>100),"Pontuação inválida",IF(D8<=20,"Muito baixo",IF(D8<=40,"Baixo",IF(D8<=60,"Moderado",IF(D8<=80,"Alto","Muito alto")))))) -> Alto | E9: =IF(E8="","",IF(OR(E8<0,E8>100),"Pontuação inválida",IF(E8<=20,"Muito baixo",IF(E8<=40,"Baixo",IF(E8<=60,"Moderado",IF(E8<=80,"Alto","Muito alto")))))) -> Moderado | F9: =IF(F8="","",IF(OR(F8<0,F8>100),"Pontuação inválida",IF(F8<=20,"Muito baixo",IF(F8<=40,"Baixo",IF(F8<=60,"Moderado",IF(F8<=80,"Alto","Muito alto")))))) -> Moderado | G9: =IF(G8="","",IF(OR(G8<0,G8>100),"Pontuação inválida",IF(G8<=20,"Muito baixo",IF(G8<=40,"Baixo",IF(G8<=60,"Moderado",IF(G8<=80,"Alto","Muito alto")))))) -> Moderado | H9: =IF(H8="","",IF(OR(H8<0,H8>100),"Pontuação inválida",IF(H8<=20,"Muito baixo",IF(H8<=40,"Baixo",IF(H8<=60,"Moderado",IF(H8<=80,"Alto","Muito alto")))))) -> Alto | I9: =IF(I8="","",IF(OR(I8<0,I8>100),"Pontuação inválida",IF(I8<=20,"Muito baixo",IF(I8<=40,"Baixo",IF(I8<=60,"Moderado",IF(I8<=80,"Alto","Muito alto")))))) -> Moderado | J9: =IF(J8="","",IF(OR(J8<0,J8>100),"Pontuação inválida",IF(J8<=20,"Muito baixo",IF(J8<=40,"Baixo",IF(J8<=60,"Moderado",IF(J8<=80,"Alto","Muito alto")))))) -> Baixo | K9: =IF(K8="","",IF(OR(K8<0,K8>100),"Pontuação inválida",IF(K8<=20,"Muito baixo",IF(K8<=40,"Baixo",IF(K8<=60,"Moderado",IF(K8<=80,"Alto","Muito alto")))))) -> Baixo
B11: ANÁLISE COMPORTAMENTAL COMPLETA | H11: PERFIL PREDOMINANTE
H12: =IF(MAX(G8+H8,J8+K8,C8+E8,F8+I8,D8*2)=J8+K8,"Perfil inseguro e sensível",IF(MAX(G8+H8,J8+K8,C8+E8,F8+I8,D8*2)=G8+H8,"Perfil lúdico e social",IF(MAX(G8+H8,J8+K8,C8+E8,F8+I8,D8*2)=F8+I8,"Perfil territorial e confrontador",IF(MAX(G8+H8,J8+K8,C8+E8,F8+I8,D8*2)=C8+E8,"Perfil predatório e perseguidor","Perfil controlador de movimento")))) -> Perfil controlador de movimento
B13: DRIVE PREDOMINANTE: | D13: {=IF(COUNT(C8:K8)<9,"",INDEX(C7:K7,1,MATCH(MAX(C8:K8),C8:K8,0)))} -> PASTOREIO
B15: =IF(H12="","", "Este cão apresenta como perfil predominante "&LOWER(H12)& IF(OR(H16="",H16=H12),".", ", acompanhado de características secundárias relacionadas ao perfil "&LOWER(H16)&".") & IF(D13="","", " O drive que aparece com maior intensidade é "&LOWER(D13)&", o que ajuda a compreender quais estímulos tendem a despertar maior interesse ou provocar respostas mais intensas no dia a dia." ) & CHAR(10)&CHAR(10)& IF(AND(G8>=61,H8>=61), "As pontuações elevadas em brincadeira e matilha indicam interesse importante por interação, proximidade social e participação em atividades com pessoas ou outros cães. Na prática, é necessário observar se essas aproximações acontecem de maneira equilibrad"&"a, se o cão respeita pausas e se consegue compreender os sinais de interrupção apresentados pelos demais.", "") & IF(AND(G8>=61,OR(J8>=61,K8>=61)), CHAR(10)&CHAR(10)& "Apesar do interesse por brincadeiras ou aproximações, os índices elevados de fuga ou congelamento sugerem que o cão pode se desorganizar quando a interação se torna intensa, imprevisível ou quando não consegue se afastar. Ele pode demonstrar vontade de pa"&"rticipar e, ao mesmo tempo, apresentar desconforto diante de determinadas aproximações.", "") & IF(AND(J8>=61,K8>=61), CHAR(10)&CHAR(10)& "A combinação entre fuga e congelamento indica insegurança relevante. Diante de situações desconfortáveis, o cão pode alternar entre tentar se afastar e permanecer imóvel. A ausência de movimento não deve ser interpretada automaticamente como tranquilidade"&", aceitação ou adaptação.", IF(OR(J8>=61,K8>=61), CHAR(10)&CHAR(10)& "Há sinais relevantes de insegurança. Durante a avaliação presencial, será importante observar a possibilidade de afastamento, o tempo necessário para explorar o ambiente e sua capacidade de recuperação emocional após situações desconfortáveis.", "")) & IF(I8>=61, CHAR(10)&CHAR(10)& "A pontuação elevada em luta sugere maior disposição para enfrentar conflitos, sustentar disputas ou responder de forma impositiva quando frustrado ou pressionado. Isso não determina que o cão será agressivo, mas exige atenção especial à comunicação social"&", à manipulação, à posse de recursos e à possibilidade de escalada de conflitos.", "") & IF(AND(C8>=61,E8>=61), CHAR(10)&CHAR(10)& "A combinação elevada entre caça e predação demonstra forte interesse por exploração, perseguição, captura e estímulos em movimento. Durante a avaliação prática, será necessário observar fixação, intensidade da perseguição, capacidade de interrupção e segu"&"rança na convivência com cães menores ou mais vulneráveis.", IF(C8>=61, CHAR(10)&CHAR(10)& "O drive de caça elevado indica forte interesse por cheiros, rastros e exploração do ambiente. Atividades de faro podem ser motivadoras, mas também será importante verificar se o cão consegue interromper a investigação e voltar sua atenção para o condutor.", "")) & IF(D8>=61, CHAR(10)&CHAR(10)& "A pontuação elevada em pastoreio indica atenção intensa aos movimentos de pessoas, cães ou grupos. Esse comportamento pode aparecer por meio de perseguições, bloqueios de passagem, mordiscadas ou tentativas de controlar a movimentação dos demais.", "") & IF(F8>=61, CHAR(10)&CHAR(10)& "O territorialismo elevado sugere maior vigilância e sensibilidade à aproximação de pessoas ou animais em espaços considerados importantes. A avaliação deve incluir a observação em entradas, portões, portas, corredores e momentos de circulação.", "") & IF(AND(I8<=20,E8<=20), CHAR(10)&CHAR(10)& "As pontuações muito baixas em luta e predação indicam que confronto direto e comportamentos de captura não aparecem como tendências predominantes nas respostas fornecidas. Ainda assim, esses resultados não eliminam riscos e precisam ser confirmados na ava"&"liação presencial.", "") & CHAR(10)&CHAR(10)& "Esta análise representa uma hipótese comportamental construída a partir das respostas da anamnese. Ela deve ser comparada com a ficha de avaliação presencial, com o contexto em que os comportamentos aparecem e com a análise técnica do avaliador." ) -> Este cão apresenta como perfil predominante perfil controlador de movimento, acompanhado de características secundárias relacionadas ao perfil tendência secundária a controlar movimentos. O drive que aparece com maior intensidade é pastoreio, o que ajuda a compreender quais estímulos tendem a despertar maior interesse ou provocar respostas mais intensas no dia a dia. A pontuação elevada em pastoreio indica atenção intensa aos movimentos de pessoas, cães ou grupos. Esse comportamento pode aparecer por meio de perseguições, bloqueios de passagem, mordiscadas ou tentativas de controlar a movimentação dos demais. Esta análise representa uma hipótese comportamental construída a partir das respostas da anamnese. Ela deve ser comparada com a ficha de avaliação presencial, com o contexto em que os comportamentos aparecem e com a análise técnica do avaliador. | H15: PERFIL SECUNDÁRIO
H16: =IF(AND(J8>=41,K8>=41),"Tendência secundária à insegurança, com possibilidade de fuga ou congelamento",IF(AND(G8>=61,H8>=41),"Tendência secundária lúdica e social",IF(AND(C8>=61,E8>=61),"Tendência secundária predatória",IF(AND(F8>=61,I8>=41),"Tendência secundária territorial ou confrontadora",IF(D8>=61,"Tendência secundária a controlar movimentos","Nenhuma tendência secundária elevada identificada"))))) -> Tendência secundária a controlar movimentos
H20: PERCEPÇÃO GERAL RESUMIDA
H21: =IF(H12="","", IF(H12="LÚDICO E SOCIAL", "Este cão demonstra forte interesse por brincadeiras, proximidade e interação social. Durante a avaliação, observe a intensidade das interações, o respeito às pausas e a capacidade de perceber os sinais de pessoas e outros cães.", IF(H12="INSEGURO E EVITATIVO", "Este cão tende a apresentar insegurança diante de situações novas ou desconfortáveis, podendo tentar se afastar, evitar aproximações ou permanecer imóvel. A avaliação deve respeitar seu tempo e observar sua recuperação emocional.", IF(H12="TERRITORIAL E VIGILANTE", "Este cão tende a permanecer atento ao ambiente e pode reagir diante da aproximação de pessoas ou animais aos espaços que considera importantes. Observe principalmente entradas, portas, portões e circulação no ambiente.", IF(H12="EXPLORATÓRIO E INVESTIGATIVO", "Este cão demonstra forte interesse por cheiros, rastros e exploração do ambiente. Durante a avaliação, observe sua capacidade de interromper a investigação, responder ao condutor e se adaptar às atividades propostas.", IF(H12="CONTROLADOR DE MOVIMENTO", "Este cão tende a acompanhar e tentar controlar a movimentação de pessoas ou animais. Durante a convivência, observe perseguições, bloqueios de passagem, mordiscadas e interferências nas brincadeiras dos outros cães.", IF(H12="CONFRONTADOR E IMPOSITIVO", "Este cão pode apresentar maior disposição para enfrentar conflitos, sustentar disputas ou responder de forma impositiva. A avaliação deve priorizar a segurança, a tolerância à frustração e a qualidade da comunicação social.", IF(H12="PREDATÓRIO", "Este cão demonstra interesse elevado por perseguição, captura e estímulos em movimento. A avaliação deve observar fixação, intensidade, capacidade de interrupção e segurança na convivência com cães menores ou vulneráveis.", "O perfil deste cão apresenta características combinadas que precisam ser analisadas junto às respostas da anamnese e ao comportamento observado presencialmente." ))))))) & IF(OR(H16="",H16=H12),"", " Como característica secundária, apresenta um perfil "&LOWER(H16)&", que também deve ser considerado durante a avaliação prática." )) -> O perfil deste cão apresenta características combinadas que precisam ser analisadas junto às respostas da anamnese e ao comportamento observado presencialmente. Como característica secundária, apresenta um perfil tendência secundária a controlar movimentos, que também deve ser considerado durante a avaliação prática.
H30: PONTOS DE ATENÇÃO
H31: =IF(COUNT(C8:K8)<9,"", IF(I8>=61, "• Avaliar com cautela a tolerância à frustração, a manipulação, a posse de recursos e a possibilidade de escalada de conflitos."&CHAR(10), "") & IF(AND(J8>=61,K8>=61), "• Garantir possibilidade de afastamento e não interpretar imobilidade como tranquilidade ou aceitação."&CHAR(10)& "• Observar o tempo necessário para o cão recuperar o equilíbrio emocional após situações desconfortáveis."&CHAR(10), IF(J8>=61, "• Permitir que o cão se afaste quando demonstrar desconforto e observar tentativas de fuga ou esquiva."&CHAR(10), IF(K8>=61, "• Não interpretar o congelamento como calma. Observar tensão corporal, imobilidade e dificuldade de responder."&CHAR(10), ""))) & IF(AND(G8>=61,OR(J8>=61,K8>=61)), "• Realizar aproximações e inserções em grupo de forma gradual, pois o interesse por interação pode coexistir com insegurança."&CHAR(10), "") & IF(AND(C8>=61,E8>=61), "• Avaliar perseguição, fixação em estímulos, intensidade da mordida e capacidade de interromper o comportamento."&CHAR(10)& "• Ter atenção especial na convivência com cães menores, filhotes ou indivíduos mais vulneráveis."&CHAR(10), IF(E8>=61, "• Observar perseguição, captura, fixação em movimento e capacidade de interrupção."&CHAR(10), IF(C8>=61, "• Observar se o cão consegue interromper a exploração e redirecionar a atenção para o condutor."&CHAR(10), ""))) & IF(D8>=61, "• Monitorar perseguições, bloqueios de passagem, mordiscadas e tentativas de controlar a movimentação de pessoas ou cães."&CHAR(10), "") & IF(F8>=61, "• Avaliar o comportamento em portas, portões, corredores, entradas e durante a aproximação de pessoas ou cães."&CHAR(10), "") & IF(G8>=61, "• Observar a intensidade das brincadeiras, o respeito às pausas e a resposta aos sinais de interrupção dos outros cães."&CHAR(10), "") & IF(H8>=61, "• Avaliar a autonomia do cão e sua reação quando precisa permanecer separado de pessoas ou do grupo."&CHAR(10), "") & IF(AND(I8<61,J8<61,K8<61,C8<61,D8<61,E8<61,F8<61,G8<61,H8<61), "• Nenhum ponto crítico se destacou exclusivamente pelas respostas da anamnese. Confirmar o perfil durante a avaliação presencial.", "") ) -> • Monitorar perseguições, bloqueios de passagem, mordiscadas e tentativas de controlar a movimentação de pessoas ou cães. • Avaliar a autonomia do cão e sua reação quando precisa permanecer separado de pessoas ou do grupo.
H42: Esta análise é baseada nas respostas do responsável e não substitui a avaliação prática do cão.

Sheet 3) Ficha Técnica de Avaliação P
B2: Ficha Técnica de Avaliação Presencial | E2: Recomendação Automática | K2: Legenda das notas
B3: Nome do cão | E3: =IF(COUNT(C10,C11,C12,C13,C14,C17,C18,C19,C20,C21,C24,C25,C26,C27,C30,C31,C32,C33,C34,C37,C38,C39,C40,C41,C42,C43)<26,"",REPT("★",ROUND(AVERAGE(C10,C11,C12,C13,C14,C17,C18,C19,C20,C21,C24,C25,C26,C27,C30,C31,C32,C33,C34,C37,C38,C39,C40,C41,C42,C43),0))&REPT("☆",5-ROUND(AVERAGE(C10,C11,C12,C13,C14,C17,C18,C19,C20,C21,C24,C25,C26,C27,C30,C31,C32,C33,C34,C37,C38,C39,C40,C41,C42,C43),0))) | K3: Não demonstrou ou apresentou comportamento inadequado. | L3: 1
B4: Responsável | E4: =IF(COUNT(C10,C11,C12,C13,C14,C17,C18,C19,C20,C21,C24,C25,C26,C27,C30,C31,C32,C33,C34,C37,C38,C39,C40,C41,C42,C43)<26,"",REPT("★",ROUND(AVERAGE(C10,C11,C12,C13,C14,C17,C18,C19,C20,C21,C24,C25,C26,C27,C30,C31,C32,C33,C34,C37,C38,C39,C40,C41,C42,C43),0))&REPT("☆",5-ROUND(AVERAGE(C10,C11,C12,C13,C14,C17,C18,C19,C20,C21,C24,C25,C26,C27,C30,C31,C32,C33,C34,C37,C38,C39,C40,C41,C42,C43),0))) | K4: Demonstrou com grande dificuldade. | L4: 2
B5: Data | E5: =IF(OR(COUNT(C17:C21)<5,C30="",C31="",COUNT(C37:C43)<7,E3=""),"", IF(OR(AVERAGE(C17:C21)<2,C30<=2,C31<=2), "🔴 REPROVAÇÃO RECOMENDADA", IF(OR(AVERAGE(C37:C43)<2,E3<3), "🟠 NOVA AVALIAÇÃO RECOMENDADA", IF(OR(AVERAGE(C17:C21)<3,AVERAGE(C37:C43)<3,E3<4), "🟡 APROVADO COM RESTRIÇÕES", "🟢 APROVADO"))) ) | K5: Demonstrou parcialmente, com ressalvas. | L5: 3
B6: Avaliador | K6: Demonstrou de forma satisfatória. | L6: 4
B7: Tempo da avaliação | K7: Demonstrou de forma consistente e segura. | L7: 5
B9: Recepção e Entrada | C9: =IF(COUNT(C10:C14)<5,"",REPT("★",ROUND(AVERAGE(C10:C14),0))&REPT("☆",5-ROUND(AVERAGE(C10:C14),0))) | E9: Observações
B10: Separação do responsável
B11: Entrada na empresa
B12: Estado emocional inicial
B13: Interesse pelo ambiente
B14: Vocalização
B16: Manipulação | C16: =IF(COUNT(C17:C21)<5,"",REPT("★",ROUND(AVERAGE(C17:C21),0))&REPT("☆",5-ROUND(AVERAGE(C17:C21),0))) | E16: Observações
B17: Toque corporal
B18: Patas
B19: Orelhas
B20: Boca
B21: Colocação/retirada da guia
B23: Passeio e Condução | C23: =IF(COUNT(C24:C27)<4,"",REPT("★",ROUND(AVERAGE(C24:C27),0))&REPT("☆",5-ROUND(AVERAGE(C24:C27),0))) | E23: Observações
B24: Caminhada
B25: Atenção ao condutor
B26: Reação aos estímulos
B27: Recuperação emocional
B29: Interação Social | C29: =IF(COUNT(C30:C34)<5,"",REPT("★",ROUND(AVERAGE(C30:C34),0))&REPT("☆",5-ROUND(AVERAGE(C30:C34),0))) | E29: Observações
B30: Interação com pessoas
B31: Interação com outros cães
B32: Convite para brincar
B33: Comunicação corporal
B34: Respeito aos sinais sociais
B36: Adaptação à Rotina | C36: =IF(COUNT(C37:C43)<7,"",REPT("★",ROUND(AVERAGE(C37:C43),0))&REPT("☆",5-ROUND(AVERAGE(C37:C43),0))) | E36: Observações
B37: Explorou o ambiente
B38: Bebeu água
B39: Aceitou alimento
B40: Fez xixi
B41: Fez cocô
B42: Conseguiu descansar
B43: Recuperou-se emocionalmente
B45: Comparação com a Anamnese | E45: Observação Geral
B46: O comportamento confirmou a anamnese?
B48: O que mais chamou sua atenção?
...

Sheet 4) Registro Geral das Avaliaçõe
B2: Registro Geral das Avaliações
B5: 📋 Avaliações realizadas | E5: 🟢 Aprovados | F5: =COUNTIF($E$15:$E$133,"Aprovado") -> 1 | G5: =F5/$B$7 -> 0.33333333
E6: 🟡 Aprovados com restrições | F6: =COUNTIF($E$15:$E$133,"Aprovado com restrição") -> 1 | G6: =F6/$B$7 -> 0.33333333
B7: =COUNTA(D:D)-1 -> 3 | E7: 🟠 Nova avaliação | F7: =COUNTIF($E$15:$E$133,"Nova avaliação") -> 1 | G7: =F7/$B$7 -> 0.33333333
E8: 🟢 Reprovados | F8: =COUNTIF($E$15:$E$133,"Reprovado") -> 0 | G8: =F8/$B$7 -> 0
E9: ❌ Desistências | F9: =COUNTIF($H$15:$H$133,"Não, dono desistiu") -> 0 | G9: =F9/$B$7 -> 0
E10: 🟢Entrou | F10: =COUNTIF($H$15:$H$133,"Sim") -> 3 | G10: =F10/$B$7 -> 1
E11: 🟠Não Entrou | F11: =COUNTIF($H$15:$H$133,"Não") -> 0 | G11: =F11/$B$7 -> 0
B14: Data | C14: Responsável | D14: Cão | E14: Resultado do avaliador | F14: Plano recomendado | G14: Frequência | H14: Entrou? | I14: Avaliador | J14: Qual foi a recomendação automática | K14: Observações
B15: 46220 | C15: Tata Pereira | D15: Eva | E15: Aprovado | F15: Trimestral | G15: 1x na semana | H15: Sim | I15: Tata | J15: APROVADO | K15: Cão tem medo mas sem agressão e demostrou uma boa recuperação emocial.
B16: 46225 | C16: Rachel | D16: Lili | E16: Aprovado com restrição | F16: Mensal | G16: 1x na semana | H16: Sim | I16: Tata | J16: REPROVAÇÃO | K16: Aprovação devido ao conhecimento do historico social do cão
B17: 46225 | C17: Joaquina | D17: Paçoca | E17: Nova avaliação | F17: Mensal | G17: 1x na semana | H17: Sim | I17: Tata | J17: APROVADO COM RESTRIÇÕES | K17: Cão precisa de aulas de adestramento individual, depois na escola e ai sim refazer uma nova avaliação

Sheet Apoio
A1: Lúdico e social: 67 + 58 = 125 | C1: Perfil analisado | D1: Cálculo | F1: A | G1: B | H1: C
A2: Inseguro e sensível: 55 + 67 = 122 | C2: Lúdico e social | D2: Brincadeira + Matilha | F2: Drive | G2: Pontuação | H2: Classificação
A3: Predatório e perseguidor: 31 + 6 = 37 | C3: Inseguro e sensível | D3: Fuga + Congelamento | F3: Caça | G3: 31 | H3: Baixo
A4: Territorial e confrontador: 35 + 7 = 42 | C4: Predatório e perseguidor | D4: Caça + Predação | F4: Pastoreio | G4: 34 | H4: Baixo
A5: Controlador de movimento: 34 × 2 = 68 | C5: Territorial e confrontador | D5: Territorialismo + Luta | F5: Predação | G5: 6 | H5: Muito baixo
C6: Controlador de movimento | D6: Pastoreio | F6: Territorialismo | G6: 35 | H6: Baixo
F7: Brincadeira | G7: 67 | H7: Alto
A9: Média | B9: Estrelas | C9: Interpretação | F9: Significado | G9: Nota | I9: Ordem de prioridade da decisão
A10: 4.2 | B10: ★★★★☆ | C10: Excelente | F10: Não demonstrou / comportamento inadequado para o critério avaliado. | G10: 1 | I10: Risco → Reprovação
A11: 3.4 | B11: ★★★☆☆ | C11: Boa | F11: Demonstrou de forma muito limitada ou com grande dificuldade. | G11: 2 | I11: Manipulação (C16) < 2.
A12: 2.6 | B12: ★★★☆☆ | C12: Atenção | F12: Demonstrou parcialmente, com algumas ressalvas. | G12: 3 | I12: Interação com pessoas (C30) ≤ 2.
A13: 1.8 | B13: ★★☆☆☆ | C13: Crítica | F13: Demonstrou de forma satisfatória durante a maior parte da avaliação. | G13: 4 | I13: Interação com cães (C31) ≤ 2.
F14: Demonstrou de forma consistente, adequada e segura durante toda a avaliação | G14: 5 | I14: Adaptação → Nova avaliação
I15: Adaptação ao ambiente (C36) < 2.
I16: Ressalvas → Aprovado com restrições
I17: Manipulação entre 2 e 2,99.
I18: Adaptação entre 2 e 2,99.
I19: Média geral entre 3 e 3,99.
I20: Aprovado
I21: Média geral ≥ 4.
I22: Nenhum fator crítico.
